Workbook

Sheet Hoja1
A1: ID | B1: TGs_mg_dL | C1: Glucose_mmol_L | D1: BMI | E1: Waist_Circumference | F1: Height | G1: Height_cm | I1: TyG_index | J1: TyG_BMI | K1: TyG_WC | L1: TyG_WHtR | M1: ABSI
A2: MI_001 | B2: 195 | C2: 4.773 | D2: 29.668407 | E2: 97.6 | F2: 1.732 | G2: =F2*100 -> 173.2 | I2: =LN(B2*(C2/2)) -> 6.1428274 | J2: =I2*D2 -> 182.24791 | K2: =I2*E2 -> 599.53996 | L2: =(I2*E2)/G2 -> 3.4615471 | M2: =E2/(D2^(2/3)) * (G2^(1/2)) -> 134.02761
A3: MI_002 | B3: 100 | C3: 4.8285 | D3: 30.428737 | E3: 89.3 | F3: 1.496 | G3: =F3*100 -> 149.6 | I3: =LN(B3*(C3/2)) -> 5.4865589 | J3: =I3*D3 -> 166.94906 | K3: =I3*E3 -> 489.94971 | L3: =(I3*E3)/G3 -> 3.2750649 | M3: =E3/(D3^(2/3)) * (G3^(1/2)) -> 112.06276
A4: MI_003 | B4: 76 | C4: 4.7175 | D4: 24.36943 | E4: 92.8 | F4: 1.831 | G4: =F4*100 -> 183.1 | I4: =LN(B4*(C4/2)) -> 5.1888652 | J4: =I4*D4 -> 126.44969 | K4: =I4*E4 -> 481.52669 | L4: =(I4*E4)/G4 -> 2.6298563 | M4: =E4/(D4^(2/3)) * (G4^(1/2)) -> 149.39242
A5: MI_005 | B5: 114 | C5: 3.552 | D5: 21.033119 | E5: 73.3 | F5: 1.696 | G5: =F5*100 -> 169.6 | I5: =LN(B5*(C5/2)) -> 5.3105621 | J5: =I5*D5 -> 111.69768 | K5: =I5*E5 -> 389.2642 | L5: =(I5*E5)/G5 -> 2.2951899 | M5: =E5/(D5^(2/3)) * (G5^(1/2)) -> 125.27982
A6: MI_006 | B6: 306 | C6: 4.4955 | D6: 26.058238 | E6: 88.2 | F6: 1.646 | G6: =F6*100 -> 164.6 | I6: =LN(B6*(C6/2)) -> 6.5335148 | J6: =I6*D6 -> 170.25188 | K6: =I6*E6 -> 576.25601 | L6: =(I6*E6)/G6 -> 3.5009478 | M6: =E6/(D6^(2/3)) * (G6^(1/2)) -> 128.74197
A7: MI_008 | B7: 126 | C7: 4.4955 | D7: 32.335392 | E7: 105.2 | F7: 1.808 | G7: =F7*100 -> 180.8 | I7: =LN(B7*(C7/2)) -> 5.6462116 | J7: =I7*D7 -> 182.57247 | K7: =I7*E7 -> 593.98146 | L7: =(I7*E7)/G7 -> 3.2852957 | M7: =E7/(D7^(2/3)) * (G7^(1/2)) -> 139.36793
A8: MI_011 | B8: 54 | C8: 4.1625 | D8: 28.312713 | E8: 76.9 | F8: 1.481 | G8: =F8*100 -> 148.1 | I8: =LN(B8*(C8/2)) -> 4.7219527 | J8: =I8*D8 -> 133.69129 | K8: =I8*E8 -> 363.11816 | L8: =(I8*E8)/G8 -> 2.4518445 | M8: =E8/(D8^(2/3)) * (G8^(1/2)) -> 100.74331
A9: MI_012 | B9: 128 | C9: 4.3845 | D9: 33.455439 | E9: 113.4 | F9: 1.701 | G9: =F9*100 -> 170.1 | I9: =LN(B9*(C9/2)) -> 5.6369587 | J9: =I9*D9 -> 188.58693 | K9: =I9*E9 -> 639.23111 | L9: =(I9*E9)/G9 -> 3.7579725 | M9: =E9/(D9^(2/3)) * (G9^(1/2)) -> 142.44725
A10: MI_013 | B10: 154 | C10: 7.437 | D10: 34.751615 | E10: 111.5 | F10: 1.675 | G10: =F10*100 -> 167.5 | I10: =LN(B10*(C10/2)) -> 6.350273 | J10: =I10*D10 -> 220.68224 | K10: =I10*E10 -> 708.05544 | L10: =(I10*E10)/G10 -> 4.2271966 | M10: =E10/(D10^(2/3)) * (G10^(1/2)) -> 135.50821
A11: MI_014 | B11: 76 | C11: 4.329 | D11: 28.492882 | E11: 90 | F11: 1.583 | G11: =F11*100 -> 158.3 | I11: =LN(B11*(C11/2)) -> 5.1029227 | J11: =I11*D11 -> 145.39698 | K11: =I11*E11 -> 459.26305 | L11: =(I11*E11)/G11 -> 2.9012195 | M11: =E11/(D11^(2/3)) * (G11^(1/2)) -> 121.38324
A12: MI_017 | B12: 446 | C12: 18.5925 | D12: 41.805259 | E12: 131.3 | F12: 1.69 | G12: =F12*100 -> 169 | I12: =LN(B12*(C12/2)) -> 8.32993 | J12: =I12*D12 -> 348.23488 | K12: =I12*E12 -> 1093.7198 | L12: =(I12*E12)/G12 -> 6.4717149 | M12: =E12/(D12^(2/3)) * (G12^(1/2)) -> 141.70575
A13: MI_018 | B13: 68 | C13: 4.218 | D13: 33.510216 | E13: 97.7 | F13: 1.481 | G13: =F13*100 -> 148.1 | I13: =LN(B13*(C13/2)) -> 4.9657216 | J13: =I13*D13 -> 166.4024 | K13: =I13*E13 -> 485.151 | L13: =(I13*E13)/G13 -> 3.2758339 | M13: =E13/(D13^(2/3)) * (G13^(1/2)) -> 114.38979
... A312: MI_457 | B312: 407 | C312: 5.106 | D312: 29.711641 | E312: 100.6 | F312: 1.752 | G312: =F312*100 -> 175.2 | I312: =LN(B312*(C312/2)) -> 6.9460823 | J312: =I312*D312 -> 206.3795 | K312: =I312*E312 -> 698.77588 | L312: =(I312*E312)/G312 -> 3.9884468 | M312: =E312/(D312^(2/3)) * (G312^(1/2)) -> 138.80782

Sheet DB_integrated_polypenols_intake
A1: ID | B1: Ciudad | C1: Sex | D1: Age | E1: Age_range | F1: ApoB_mg_dL | G1: HDL_mg_dL | H1: HDL_class | I1: VLDL_mg_dL | J1: LDL_mg_dL | K1: T.Cholesterol_mg_dL_ | L1: TGs_mg_dL | M1: Atherogenic_index | N1: Atherogenic_index_AIP | O1: Atherogenic_index_AIP_Class | P1: Creatinine_mg_dL_ | Q1: hsCRP_mg_L | R1: Glucose_mg_dL | S1: HbA1c | T1: Leptina_ng_mL | U1: Adiponectin_ug_ml | V1: Lep_Adip | W1: Insulin_uU_mL | X1: Glucose_mmol_L | Y1: beta_cell_function | Z1: HOMA-B | AA1: Insulin_Sensibility | AB1: HOMA-S | AC1: HOMA_IR | AD1: Quicki | AE1: Weight | AF1: Height | AG1: BMI | AH1: BMI_CLAS | AI1: Perc_fat | AJ1: Waist_Circumference | AK1: WC.CLAS | AL1: WC8689 | AM1: Smoking_status | AN1: Alcohol_use | AO1: Physical_activity_IPAQ | AP1: Systolic_BP | AQ1: Diastolic_BP | AR1: Calories | AS1: FIBER | AT1: Ca | AU1: P | AV1: Fe_total | AW1: Na | AX1: K | AY1: Mg | AZ1: Zn | BA1: Cu | BB1: Mn | BC1: Vit_A_ER | BD1: B1 | BE1: B2 | BF1: B3 | BG1: Ac_pantoenico | BH1: B6 | BI1: Folic | BJ1: B12 | BK1: Vit_C | BL1: Acetic_A_Feces | BM1: Propionic_A_Feces | BN1: Butyric_A_Feces | BO1: Isobutyric_A_Feces | BP1: chs_class | BQ1: a_hypertension | BR1: a_triglycerides | BS1: a_cholesterol | BT1: a_glucose | BU1: a_inflammation | BV1: a_insulin_resist | BW1: Acetic_A_Plasma | BX1: Propionic_A_Plasma | BY1: Isobutyric_A_Plasmas | BZ1: Butyric_A_Plasma | CA1: Valeric_A_Plasma | CB1: DII_score | CC1: E_DII | CD1: E_DII_tertiles | CE1: E_DII_class | CF1: RFM | CH1: Prevotella | CI1: Lachnospiraceae | CJ1: Pathogen | CK1: Akkermansia-Bacteroidales | CL1: Ruminococcaceae | CM1: TPC_Folin | CN1: TPC_Folin_1000 | CO1: TPC_Chr | CP1: Chromatography_only | CQ1: Chromatography_AH | CR1: T.Flavonoids | CS1: T.Phenolic.A | CT1: Other_polyphenols_chr | CU1: Other_polyphenols_chrah | CV1: T.Other_polyphenols | CW1: Lignans_chr.otu | CX1: Lignans_chrah.otu | CY1: T._Lignans | CZ1: Stilbenes_chr | DA1: S.Alkylphenols_chr | DB1: S.Anthocyanins_chr | DC1: S.Curcuminoids_chr | DD1: S.Flavanols_chr | DE1: S.Flavanones_chr | DF1: S.Flavanones_chrah | DG1: T.Subgroup.Flavanones | DH1: S.Flavones_chr | DI1: S.Flavones_chrah | DJ1: T.Subgroup.Flavones | DK1: S.Flavonols_chr | DL1: S.Flavonols_chrah | DM1: T.Subgroup.Flavonols | DN1: S.Hydroxybenzoic_acids_chr | DO1: S.Hydroxybenzoic_acids_chrah | DP1: T.Subgroup.Hydroxybenzoic_acids | DQ1: S.Hydroxycinnamic_acids_chr | DR1: S.Hydroxycinnamic_acids_chrah | DS1: T.Subgroup.Hydroxycinnamic_acids | DT1: S.Lignans_chr | DU1: S.Lignans_chrah | DV1: T.Subgroup.Lignans | DW1: TPC_Folin_Tertil | DX1: TPC_Chr_Tertil | DY1: T.Flavonoids_Tertil | DZ1: T.Phenolic.A_Tertil | EA1: TPC_Folin_KCAL_Adj | EB1: TPC_Folin_KCAL_Adj510 | EC1: TPC_Chr_KCAL_Adj | ED1: T.Flavonoids_KCAL_Adj | EE1: T.Phenolic.A_KCAL_Adj | EF1: TPC_Folin_Tertil_Kcal_Adj | EG1: TPC_Chr_Tertil_Kcal_Adj | EH1: T.Flavonoids_Tertil_Kcal_Adj | EI1: T.Phenolic.A_Tertil_Kcal_Adj | EJ1: Actividad fisica | EK1: Alcohol | EL1: Tabaquismo_bin | EM1: Tabaquismo_st | EN1: MISREP_CV_REN_2000 | EO1: SD1_MISREP_Huang_2000
A2: MI_001 | B2: Medellín | C2: Men | D2: 36 | E2: 18-40 | F2: 145 | G2: 38 | H2: Low | I2: 39 | J2: 93 | K2: 170 | L2: 195 | M2: 4.4736842 | N2: =LOG10(L2/G2) -> 0.71025101 | O2: =IF(N2<0.1,"Low", IF(N2<=0.26, "Medium", "High")) -> High | P2: 238.1 | Q2: 1.71 | R2: 86 | S2: 5.47 | T2: 8.24 | U2: 5.33 | V2: 1.5459662 | W2: 15.09 | X2: 4.773 | Y2: 164.4 | Z2: 237.07777 | AA2: 52.4 | AB2: 31.23934 | AC2: 3.201092 | AD2: 0.32080916 | AE2: 89 | AF2: 1.732 | AG2: 29.668407 | AH2: Overweight | AI2: 37.550852 | AJ2: 97.6 | AK2: Central.Obesity | AL2: Abdominal obesity | AM2: No | AN2: No | AO2: Vigorous | AP2: 146 | AQ2: 99 | AR2: 1771.49 | AS2: 18.9036 | AT2: 398.486 | AU2: 914.752 | AV2: 12.5163 | AW2: 1175.25 | AX2: 3091.55 | AY2: 262.821 | AZ2: 9.88282 | BA2: 1.42345 | BB2: 4.85994 | BC2: 584.185 | BD2: 0.908231 | BE2: 1.66133 | BF2: 17.023 | BG2: 4.63822 | BH2: 1.37515 | BI2: 355.183 | BJ2: 7.44281 | BK2: 138.548 | BL2: 50.70667 | BM2: 29.783369 | BN2: 14.501366 | BO2: 2.860847 | BP2: Abnormal | BQ2: TRUE | BR2: TRUE | BS2: TRUE | BT2: FALSE | BU2: FALSE | BV2: TRUE | BW2: NA | BX2: NA | BY2: NA | BZ2: NA | CA2: NA | CB2: 0.64832725 | CC2: 0.36607976 | CD2: =IF(CC2<=_xlfn.PERCENTILE.EXC(CC$2:CC$312, 1/3), "Low", IF(CC2<=_xlfn.PERCENTILE.EXC(CC$2:CC$312, 2/3), "Medium", "High")) -> High | CE2: =IF(CC2<MEDIAN(CC2:CC460),"antiinflamatoria","proinflamatoria") -> proinflamatoria | CF2: 28.508197 | CG2: High-fat | CH2: 0.12843216 | CI2: 0.24201771 | CJ2: 0.056390305 | CK2: 0.061667114 | CL2: 0.33592702 | CM2: 2358.252 | CN2: =IF(CM2>1000, "High","low") -> High | CO2: 2077.596 | CP2: 1473.834 | CQ2: 603.762 | CR2: 514.473 | CS2: 1521.643 | CT2: 12.573 | CU2: 0 | CV2: 12.573 | CW2: 0.07 | CX2: 28.348 | CY2: 28.418 | CZ2: 0.49 | DA2: 1.566 | DB2: 102.203 | DC2: 0 | DD2: 375.408 | DE2: 0.045 | DF2: 0 | DG2: 0.045 | DH2: 3.97 | DI2: 0 | DJ2: 3.97 | DK2: 25.495 | DL2: 7.336 | DM2: 32.83 | DN2: 8.169 | DO2: 64.349 | DP2: 72.519 | DQ2: 945.37 | DR2: 503.705 | DS2: 1449.075 | DT2: 0.07 | DU2: 28.348 | DV2: 28.418 | DW2: HIGH | DX2: HIGH | DY2: HIGH | DZ2: HIGH | EA2: 1331.225 | EB2: =IF(EA2<510,"low","high") -> high | EC2: 1172.796 | ED2: 290.418 | EE2: 858.962 | EF2: HIGH | EG2: HIGH | EH2: HIGH | EI2: HIGH | EJ2: High | EK2: Never | EL2: No | EM2: Never | EN2: Plausible_reporter | EO2: Plausible_reporter
A3: MI_002 | B3: Medellín | C3: Female | D3: 40 | E3: 18-40 | F3: 194 | G3: 52 | H3: Normal | I3: 20 | J3: 130 | K3: 202 | L3: 100 | M3: 3.8846154 | N3: =LOG10(L3/G3) -> 0.28399666 | O3: =IF(N3<0.1,"Low", IF(N3<=0.26, "Medium", "High")) -> High | P3: 174 | Q3: 0.32 | R3: 87 | S3: 5.81 | T3: 15.99 | U3: 2.57 | V3: 6.2217899 | W3: 13.57 | X3: 4.8285 | Y3: 149.6 | Z3: 204.29055 | AA3: 57.9 | AB3: 34.339221 | AC3: 2.912122 | AD3: 0.32509442 | AE3: 68.1 | AF3: 1.496 | AG3: 30.428737 | AH3: Obesity | AI3: 41.009938 | AJ3: 89.3 | AK3: Central.Obesity | AL3: Abdominal obesity | AM3: No | AN3: No | AO3: Vigorous | AP3: 121 | AQ3: 92 | AR3: 1907.88 | AS3: 12.8072 | AT3: 371.436 | AU3: 789.12 | AV3: 11.8963 | AW3: 1358.08 | AX3: 2363.98 | AY3: 192.844 | AZ3: 10.2749 | BA3: 0.953254 | BB3: 2.6991 | BC3: 557.06 | BD3: 0.734734 | BE3: 1.35422 | BF3: 13.8384 | BG3: 4.27433 | BH3: 1.36977 | BI3: 292.189 | BJ3: 7.07541 | BK3: 88.0594 | BL3: 26.363714 | BM3: 7.4569935 | BN3: 2.0536974 | BO3: 0.3514284 | BP3: Healthy | BQ3: TRUE | BR3: FALSE | BS3: FALSE | BT3: FALSE | BU3: FALSE | BV3: FALSE | BW3: 66.581879 | BX3: 17.227598 | BY3: 7.565891 | BZ3: 2.9983526 | CA3: 14.298405 | CB3: 1.6717028 | CC3: 0.87615451 | CD3: =IF(CC3<=_xlfn.PERCENTILE.EXC(CC$2:CC$312, 1/3), "Low", IF(CC3<=_xlfn.PERCENTILE.EXC(CC$2:CC$312, 2/3), "Medium", "High")) -> High | CE3: =IF(CC3<MEDIAN(CC3:CC460),"antiinflamatoria","proinflamatoria") -> proinflamatoria | CF3: 42.494961 | CG3: High-fat | CH3: 0.048837151 | CI3: 0.11060327 | CJ3: 0.080098987 | CK3: 0.27794753 | CL3: 0.17577839 | CM3: 797.09 | CN3: =IF(CM3>1000, "High","low") -> low | CO3: 658.269 | CP3: 425.019 | CQ3: 233.25 | CR3: 5.193 | CS3: 640.761 | CT3: 6.921 | CU3: 0 | CV3: 6.921 | CW3: 0 | CX3: 5.394 | CY3: 5.394 | CZ3: 0 | DA3: 2.659 | DB3: 0 | DC3: 0 | DD3: 0.196 | DE3: 0.016 | DF3: 0.117 | DG3: 0.134 | DH3: 0 | DI3: 0.027 | DJ3: 0.027 | DK3: 3.567 | DL3: 1.268 | DM3: 4.836 | DN3: 0.164 | DO3: 1.139 | DP3: 1.304 | DQ3: 414.131 | DR3: 225.282 | DS3: 639.413 | DT3: 0 | DU3: 5.394 | DV3: 5.394 | DW3: MEDIUM | DX3: MEDIUM | DY3: LOW | DZ3: HIGH | EA3: 417.789 | EB3: =IF(EA3<510,"low","high") -> low | EC3: 345.026 | ED3: 2.722 | EE3: 335.85 | EF3: MEDIUM | EG3: MEDIUM | EH3: LOW | EI3: HIGH | EJ3: High | EK3: Never | EL3: No | EM3: Never | EN3: Plausible_reporter | EO3: Plausible_reporter
A4: MI_003 | B4: Medellín | C4: Men | D4: 53 | E4: 41-60 | F4: 161 | G4: 51 | H4: Normal | I4: 15 | J4: 119 | K4: 185 | L4: 76 | M4: 3.627451 | N4: =LOG10(L4/G4) -> 0.17324342 | O4: =IF(N4<0.1,"Low", IF(N4<=0.26, "Medium", "High")) -> Medium | P4: 287.2 | Q4: 1.84 | R4: 85 | S4: 5.55 | T4: 0.73 | U4: 3.44 | V4: 0.2122093 | W4: 6.28 | X4: 4.7175 | Y4: 93.2 | Z4: 103.16222 | AA4: 124.1 | AB4: 75.94706 | AC4: 1.3167067 | AD4: 0.36612483 | AE4: 81.7 | AF4: 1.831 | AG4: 24.36943 | AH4: Normal | AI4: 34.020382 | AJ4: 92.8 | AK4: Central.Obesity | AL4: Abdominal obesity | AM4: No | AN4: No | AO4: Vigorous | AP4: 127 | AQ4: 92 | AR4: 1801.75 | AS4: 13.456 | AT4: 392.781 | AU4: 797.58 | AV4: 11.3643 | AW4: 663.655 | AX4: 2623.48 | AY4: 206.965 | AZ4: 9.70054 | BA4: 1.20799 | BB4: 2.78184 | BC4: 596.267 | BD4: 1.34948 | BE4: 1.55709 | BF4: 24.0108 | BG4: 7.10066 | BH4: 1.42279 | BI4: 267.949 | BJ4: 7.42483 | BK4: 177.954 | BL4: 7.4565408 | BM4: 6.827195 | BN4: 5.7142122 | BO4: 0.03816311 | BP4: Healthy | BQ4: TRUE | BR4: FALSE | BS4: FALSE | BT4: FALSE | BU4: FALSE | BV4: FALSE | BW4: NA | BX4: NA | BY4: NA | BZ4: NA | CA4: NA | CB4: 0.45580349 | CC4: 0.25294311 | CD4: =IF(CC4<=_xlfn.PERCENTILE.EXC(CC$2:CC$312, 1/3), "Low", IF(CC4<=_xlfn.PERCENTILE.EXC(CC$2:CC$312, 2/3), "Medium", "High")) -> Medium | CE4: =IF(CC4<MEDIAN(CC4:CC460),"antiinflamatoria","proinflamatoria") -> proinflamatoria | CF4: 24.538793 | CG4: High-fat | CH4: 0.079271755 | CI4: 0.73606147 | CJ4: 0.16051445 | CK4: 0.009988308 | CL4: 3.34e-05 | CM4: 1215.964 | CN4: =IF(CM4>1000, "High","low") -> High | CO4: 1013.403 | CP4: 700.31 | CQ4: 313.093 | CR4: 11.726 | CS4: 989.353 | CT4: 7.765 | CU4: 0 | CV4: 7.765 | CW4: 0 | CX4: 4.559 | CY4: 4.559 | CZ4: 0 | DA4: 0.79 | DB4: 0 | DC4: 0 | DD4: 11.635 | DE4: 0 | DF4: 0 | DG4: 0 | DH4: 0 | DI4: 0.003 | DJ4: 0.003 | DK4: 0 | DL4: 0.087 | DM4: 0.087 | DN4: 0.168 | DO4: 0.714 | DP4: 0.882 | DQ4: 680.742 | DR4: 307.729 | DS4: 988.471 | DT4: 0 | DU4: 4.559 | DV4: 4.559 | DW4: MEDIUM | DX4: HIGH | DY4: LOW | DZ4: HIGH | EA4: 674.879 | EB4: =IF(EA4<510,"low","high") -> high | EC4: 562.455 | ED4: 6.508 | EE4: 549.107 | EF4: HIGH | EG4: HIGH | EH4: LOW | EI4: HIGH | EJ4: High | EK4: Never | EL4: No | EM4: Never | EN4: Plausible_reporter | EO4: Plausible_reporter
A5: MI_004 | B5: Medellín | C5: Men | D5: 58 | E5: 41-60 | F5: 177 | G5: 59 | H5: Normal | I5: 20 | J5: 120 | K5: 199 | L5: 99 | M5: 3.3728814 | N5: =LOG10(L5/G5) -> 0.22478318 | O5: =IF(N5<0.1,"Low", IF(N5<=0.26, "Medium", "High")) -> Medium | P5: 121.1 | Q5: 0.86 | R5: 96 | S5: 5.63 | T5: 0.64 | U5: 12.37 | V5: 0.051738076 | W5: 6.54 | X5: 5.328 | Y5: 75.1 | Z5: 71.553611 | AA5: 115.5 | AB5: 64.571452 | AC5: 1.548672 | AD5: 0.35691605 | AE5: 66.8 | AF5: 1.757 | AG5: 21.638788 | AH5: Normal | AI5: 30.640649 | AJ5: 84.7 | AK5: Central.Obesity | AL5: Normal | AM5: No | AN5: No | AO5: Vigorous | AP5: 97 | AQ5: 59 | AR5: 1573.49 | AS5: 16.1338 | AT5: 799.755 | AU5: 1166.71 | AV5: 12.4575 | AW5: 1034.02 | AX5: 2724.94 | AY5: 229.234 | AZ5: 10.733 | BA5: 1.1141 | BB5: 2.68538 | BC5: 807.204 | BD5: 1.01088 | BE5: 1.8481 | BF5: 16.4262 | BG5: 4.91171 | BH5: 1.43836 | BI5: 323.679 | BJ5: 7.22339 | BK5: 153.856 | BL5: 13.464381 | BM5: 3.5852428 | BN5: 1.5412695 | BO5: 0.25111173 | BP5: Abnormal | BQ5: TRUE | BR5: FALSE | BS5: TRUE | BT5: FALSE | BU5: FALSE | BV5: FALSE | BW5: 56.424786 | BX5: 17.167625 | BY5: 6.3225581 | BZ5: 2.0557708 | CA5: 10.256934 | CB5: -0.11540175 | CC5: -0.073364111 | CD5: =IF(CC5<=_xlfn.PERCENTILE.EXC(CC$2:CC$312, 1/3), "Low", IF(CC5<=_xlfn.PERCENTILE.EXC(CC$2:CC$312, 2/3), "Medium", "High")) -> Medium | CE5: =IF(CC5<MEDIAN(CC5:CC460),"antiinflamatoria","proinflamatoria") -> antiinflamatoria | CF5: 22.512397 | CG5: High-fat | CH5: 0.26156337 | CI5: 0.35349214 | CJ5: 0.05226642 | CK5: 0.020120259 | CL5: 0.062904718 | CM5: 1291.03 | CN5: =IF(CM5>1000, "High","low") -> High | CO5: 1110.581 | CP5: 687.856 | CQ5: 422.724 | CR5: 94.895 | CS5: 895.324 | CT5: 6.926 | CU5: 0 | CV5: 6.926 | CW5: 0 | CX5: 113.359 | CY5: 113.359 | CZ5: 0.076 | DA5: 0.705 | DB5: 14.6 | DC5: 0 | DD5: 49.374 | DE5: 0 | DF5: 0 | DG5: 0 | DH5: 0.067 | DI5: 0.267 | DJ5: 0.334 | DK5: 21.161 | DL5: 9.378 | DM5: 30.539 | DN5: 1.608 | DO5: 15.236 | DP5: 16.844 | DQ5: 594.021 | DR5: 284.459 | DS5: 878.48 | DT5: 0 | DU5: 113.359 | DV5: 113.359 | DW5: MEDIUM | DX5: HIGH | DY5: MEDIUM | DZ5: HIGH | EA5: 820.488 | EB5: =IF(EA5<510,"low","high") -> high | EC5: 705.807 | ED5: 60.309 | EE5: 569.005 | EF5: HIGH | EG5: HIGH | EH5: MEDIUM | EI5: HIGH | EJ5: High | EK5: Never | EL5: No | EM5: Never | EN5: Under_reporter | EO5: Under_reporter
A6: MI_005 | B6: Medellín | C6: Female | D6: 44 | E6: 41-60 | F6: 112 | G6: 73 | H6: Normal | I6: 23 | J6: 63 | K6: 159 | L6: 114 | M6: 2.1780822 | N6: =LOG10(L6/G6) -> 0.19358199 | O6: =IF(N6<0.1,"Low", IF(N6<=0.26, "Medium", "High")) -> Medium | P6: 45.1 | Q6: 0.43 | R6: 64 | S6: 5.3 | T6: 12.25 | U6: 28.21 | V6: 0.43424318 | W6: 6.66 | X6: 3.552 | Y6: 172 | Z6: 2561.5385 | AA6: 127.3 | AB6: 95.112004 | AC6: 1.051392 | AD6: 0.37971062 | AE6: 60.5 | AF6: 1.696 | AG6: 21.033119 | AH6: Normal | AI6: 35.292696 | AJ6: 73.3 | AK6: Normal | AL6: Normal | AM6: Yes | AN6: Yes | AO6: Vigorous | AP6: 109 | AQ6: 74 | AR6: 2211.42 | AS6: 21.4724 | AT6: 404.349 | AU6: 937.622 | AV6: 14.2588 | AW6: 1381.54 | AX6: 4460.18 | AY6: 254.658 | AZ6: 10.8368 | BA6: 1.68263 | BB6: 3.07767 | BC6: 826.435 | BD6: 1.23758 | BE6: 1.68742 | BF6: 16.597 | BG6: 5.13946 | BH6: 2.29504 | BI6: 344.378 | BJ6: 7.14631 | BK6: 313.462 | BL6: 4.930575 | BM6: 1.0200424 | BN6: 0.22303216 | BO6: 0 | BP6: Abnormal | BQ6: TRUE | BR6: FALSE | BS6: TRUE | BT6: FALSE | BU6: FALSE | BV6: FALSE | BW6: 40.980047 | BX6: 15.646197 | BY6: 5.7817664 | BZ6: 2.4794914 | CA6: 9.4219261 | CB6: -1.5069869 | CC6: -0.68158611 | CD6: =IF(CC6<=_xlfn.PERCENTILE.EXC(CC$2:CC$312, 1/3), "Low", IF(CC6<=_xlfn.PERCENTILE.EXC(CC$2:CC$312, 2/3), "Medium", "High")) -> Low | CE6: =IF(CC6<MEDIAN(CC6:CC460),"antiinflamatoria","proinflamatoria") -> antiinflamatoria | CF6: 29.72442 | CG6: Normal | CH6: 0.000302115 | CI6: 0.37175227 | CJ6: 0.034516616 | CK6: 0.18066465 | CL6: 0.000679758 | CM6: 1242.238 | CN6: =IF(CM6>1000, "High","low") -> High | CO6: 247.292 | CP6: 132.09 | CQ6: 115.202 | CR6: 87.692 | CS6: 144.355 | CT6: 0.455 | CU6: 0 | CV6: 0.455 | CW6: 0 | CX6: 14.791 | CY6: 14.791 | CZ6: 0 | DA6: 0.447 | DB6: 0 | DC6: 0 | DD6: 73.136 | DE6: 1.614 | DF6: 2.109 | DG6: 3.722 | DH6: 4.348 | DI6: 0.335 | DJ6: 4.683 | DK6: 3.186 | DL6: 2.965 | DM6: 6.151 | DN6: 0.565 | DO6: 5.558 | DP6: 6.124 | DQ6: 48.744 | DR6: 89.403 | DS6: 138.147 | DT6: 0 | DU6: 14.791 | DV6: 14.791 | DW6: MEDIUM | DX6: LOW | DY6: MEDIUM | DZ6: MEDIUM | EA6: 561.738 | EB6: =IF(EA6<510,"low","high") -> high | EC6: 111.825 | ED6: 39.654 | EE6: 65.277 | EF6: MEDIUM | EG6: LOW | EH6: MEDIUM | EI6: MEDIUM | EJ6: High | EK6: Moderate drinker | EL6: Yes | EM6: Current | EN6: Plausible_reporter | EO6: Plausible_reporter
A7: MI_006 | B7: Medellín | C7: Men | D7: 43 | E7: 41-60 | F7: 164 | G7: 41 | H7: Normal | I7: 61 | J7: 76 | K7: 178 | L7: 306 | M7: 4.3414634 | N7: =LOG10(L7/G7) -> 0.87293757 | O7: =IF(N7<0.1,"Low", IF(N7<=0.26, "Medium", "High")) -> High | P7: 126.7 | Q7: 1.47 | R7: 81 | S7: 5.5 | T7: 1.53 | U7: 6.2 | V7: 0.24677419 | W7: 9.25 | X7: 4.4955 | Y7: 133.1 | Z7: 185.83626 | AA7: 85.9 | AB7: 54.108162 | AC7: 1.84815 | AD7: 0.34739628 | AE7: 70.6 | AF7: 1.646 | AG7: 26.058238 | AH7: Overweight | AI7: 34.747373 | AJ7: 88.2 | AK7: Central.Obesity | AL7: Normal | AM7: No | AN7: No | AO7: Moderate | AP7: 129 | AQ7: 83 | AR7: 2024.59 | AS7: 14.9162 | AT7: 664.086 | AU7: 1051.93 | AV7: 16.4337 | AW7: 1304.5 | AX7: 3130.73 | AY7: 221.634 | AZ7: 10.1849 | BA7: 1.26617 | BB7: 3.24282 | BC7: 1157.33 | BD7: 1.16729 | BE7: 1.93663 | BF7: 15.051 | BG7: 5.23267 | BH7: 1.76864 | BI7: 413.701 | BJ7: 7.03612 | BK7: 134.591 | BL7: 0 | BM7: 0 | BN7: 0 | BO7: 0 | BP7: Abnormal | BQ7: FALSE | BR7: TRUE | BS7: TRUE | BT7: FALSE | BU7: FALSE | BV7: FALSE | BW7: 30.10226 | BX7: 9.9790076 | BY7: 2.4179386 | BZ7: 1.3007114 | CA7: 4.4506583 | CB7: -0.20697779 | CC7: -0.10221126 | CD7: =IF(CC7<=_xlfn.PERCENTILE.EXC(CC$2:CC$312, 1/3), "Low", IF(CC7<=_xlfn.PERCENTILE.EXC(CC$2:CC$312, 2/3), "Medium", "High")) -> Medium | CE7: =IF(CC7<MEDIAN(CC7:CC460),"antiinflamatoria","proinflamatoria") -> antiinflamatoria | CF7: 26.675737 | CG7: High-fat | CH7: 0.05868517 | CI7: 0.35050374 | CJ7: 0.004037791 | CK7: 0.098063429 | CL7: 0.13044416 | CM7: 491.546 | CN7: =IF(CM7>1000, "High","low") -> low | CO7: 409.751 | CP7: 400.112 | CQ7: 9.639 | CR7: 383.705 | CS7: 24.337 | CT7: 0.039 | CU7: 0 | CV7: 0.039 | CW7: 0 | CX7: 1.67 | CY7: 1.67 | CZ7: 0 | DA7: 0 | DB7: 0 | DC7: 0 | DD7: 33.581 | DE7: 0 | DF7: 0 | DG7: 0 | DH7: 0 | DI7: 0.001 | DJ7: 0.001 | DK7: 349.654 | DL7: 0.424 | DM7: 350.077 | DN7: 0.121 | DO7: 0.284 | DP7: 0.405 | DQ7: 16.67 | DR7: 7.258 | DS7: 23.928 | DT7: 0 | DU7: 1.67 | DV7: 1.67 | DW7: LOW | DX7: MEDIUM | DY7: HIGH | DZ7: LOW | EA7: 242.788 | EB7: =IF(EA7<510,"low","high") -> low | EC7: 202.387 | ED7: 189.522 | EE7: 12.021 | EF7: LOW | EG7: MEDIUM | EH7: HIGH | EI7: LOW | EJ7: Moderate | EK7: Never | EL7: No | EM7: Never | EN7: Plausible_reporter | EO7: Plausible_reporter
A8: MI_007 | B8: Medellín | C8: Men | D8: 20 | E8: 18-40 | F8: 179 | G8: 34 | H8: Low | I8: 37 | J8: 101 | K8: 172 | L8: 186 | M8: 5.0588235 | N8: =LOG10(L8/G8) -> 0.73803403 | O8: =IF(N8<0.1,"Low", IF(N8<=0.26, "Medium", "High")) -> High | P8: 164.4 | Q8: 1.68 | R8: 75 | S8: 5.4 | T8: 3.07 | U8: 4.56 | V8: 0.67324561 | W8: 6.09 | X8: 4.1625 | Y8: 117.6 | Z8: 183.84906 | AA8: 132.5 | AB8: 88.758709 | AC8: 1.12665 | AD8: 0.3754305 | AE8: 59.1 | AF8: 1.719 | AG8: 20.000264 | AH8: Normal | AI8: 30.844561 | AJ8: 73 | AK8: Normal | AL8: Normal | AM8: No | AN8: Yes | AO8: Light | AP8: 110 | AQ8: 74 | AR8: 2873.47 | AS8: 38.7493 | AT8: 731.104 | AU8: 2139.1 | AV8: 20.293 | AW8: 805.025 | AX8: 5553.79 | AY8: 487.868 | AZ8: 11.6089 | BA8: 4.17021 | BB8: 4.51327 | BC8: 695.759 | BD8: 1.89943 | BE8: 2.02622 | BF8: 21.8028 | BG8: 8.37749 | BH8: 1.07398 | BI8: 684.583 | BJ8: 6.97813 | BK8: 116.219 | BL8: 11.262918 | BM8: 3.0313965 | BN8: 3.512677 | BO8: 0.021787394 | BP8: Abnormal | BQ8: FALSE | BR8: TRUE | BS8: TRUE | BT8: FALSE | BU8: FALSE | BV8: FALSE | BW8: 67.561273 | BX8: 12.941145 | BY8: 5.8223502 | BZ8: 1.303357 | CA8: 6.1466059 | CB8: -0.95733707 | CC8: -0.33321861 | CD8: =IF(CC8<=_xlfn.PERCENTILE.EXC(CC$2:CC$312, 1/3), "Low", IF(CC8<=_xlfn.PERCENTILE.EXC(CC$2:CC$312, 2/3), "Medium", "High")) -> Low | CE8: =IF(CC8<MEDIAN(CC8:CC460),"antiinflamatoria","proinflamatoria") -> antiinflamatoria | CF8: 16.90411 | CG8: Normal | CH8: 0.080580969 | CI8: 0.42161575 | CJ8: 0.009949863 | CK8: 0.060862149 | CL8: 0.18213418 | CM8: 9169.86 | CN8: =IF(CM8>1000, "High","low") -> High | CO8: 792.333 | CP8: 768.818 | CQ8: 23.515 | CR8: 755.306 | CS8: 36.74 | CT8: 0.091 | CU8: 0 | CV8: 0.091 | CW8: 0 | CX8: 0.011 | CY8: 0.011 | CZ8: 0.185 | DA8: 0.004 | DB8: 0 | DC8: 0 | DD8: 751.12 | DE8: 0 | DF8: 0 | DG8: 0 | DH8: 1.95 | DI8: 0 | DJ8: 1.95 | DK8: 2.237 | DL8: 0 | DM8: 2.237 | DN8: 1.461 | DO8: 10.832 | DP8: 12.292 | DQ8: 11.776 | DR8: 12.672 | DS8: 24.448 | DT8: 0 | DU8: 0.011 | DV8: 0.011 | DW8: HIGH | DX8: HIGH | DY8: HIGH | DZ8: LOW | EA8: 3191.215 | EB8: =IF(EA8<510,"low","high") -> high | EC8: 275.741 | ED8: 262.855 | EE8: 12.786 | EF8: HIGH | EG8: MEDIUM | EH8: HIGH | EI8: LOW | EJ8: Low | EK8: Moderate drinker | EL8: No | EM8: Never | EN8: Over_reporter | EO8: Over_reporter
A9: MI_008 | B9: Medellín | C9: Men | D9: 32 | E9: 18-40 | F9: 148 | G9: 42 | H9: Normal | I9: 25 | J9: 85 | K9: 152 | L9: 126 | M9: 3.6190476 | N9: =LOG10(L9/G9) -> 0.47712125 | O9: =IF(N9<0.1,"Low", IF(N9<=0.26, "Medium", "High")) -> High | P9: 260.2 | Q9: 0.91 | R9: 81 | S9: 4.9 | T9: 4.77 | U9: 2.82 | V9: 1.6914894 | W9: 10.68 | X9: 4.4955 | Y9: 146.6 | Z9: 214.56554 | AA9: 74.6 | AB9: 46.863343 | AC9: 2.133864 | AD9: 0.34002195 | AE9: 105.7 | AF9: 1.808 | AG9: 32.335392 | AH9: Obesity | AI9: 37.406417 | AJ9: 105.2 | AK9: Central.Obesity | AL9: Abdominal obesity | AM9: No | AN9: Yes | AO9: Vigorous | AP9: 169 | AQ9: 106 | AR9: 1666.92 | AS9: 14.7785 | AT9: 641.737 | AU9: 1188.15 | AV9: 10.5119 | AW9: 991.524 | AX9: 2769.65 | AY9: 231.308 | AZ9: 9.63526 | BA9: 1.19844 | BB9: 3.16521 | BC9: 583.495 | BD9: 0.742417 | BE9: 1.43203 | BF9: 20.1113 | BG9: 5.03112 | BH9: 1.40707 | BI9: 287.521 | BJ9: 8.02647 | BK9: 102.53 | BL9: 17.298345 | BM9: 4.849069 | BN9: 1.7427146 | BO9: 0.21089005 | BP9: Healthy | BQ9: TRUE | BR9: FALSE | BS9: FALSE | BT9: FALSE | BU9: FALSE | BV9: FALSE | BW9: NA | BX9: NA | BY9: NA | BZ9: NA | CA9: NA | CB9: 1.0756856 | CC9: 0.6452823 | CD9: =IF(CC9<=_xlfn.PERCENTILE.EXC(CC$2:CC$312, 1/3), "Low", IF(CC9<=_xlfn.PERCENTILE.EXC(CC$2:CC$312, 2/3), "Medium", "High")) -> High | CE9: =IF(CC9<MEDIAN(CC9:CC460),"antiinflamatoria","proinflamatoria") -> proinflamatoria | CF9: 29.627376 | CG9: High-fat | CH9: 0.18187891 | CI9: 0.38926931 | CJ9: 0.27244259 | CK9: 0.054697286 | CL9: 0.052066806 | CM9: 821.399 | CN9: =IF(CM9>1000, "High","low") -> low | CO9: 454.44 | CP9: 389.771 | CQ9: 64.669 | CR9: 330.449 | CS9: 119.762 | CT9: 0 | CU9: 0 | CV9: 0 | CW9: 0 | CX9: 3.981 | CY9: 3.981 | CZ9: 0.247 | DA9: 0 | DB9: 191.413 | DC9: 0 | DD9: 112.569 | DE9: 0 | DF9: 0 | DG9: 0 | DH9: 0.048 | DI9: 0.018 | DJ9: 0.065 | DK9: 16.984 | DL9: 9.418 | DM9: 26.402 | DN9: 55.682 | DO9: 41.679 | DP9: 97.361 | DQ9: 12.828 | DR9: 9.573 | DS9: 22.401 | DT9: 0 | DU9: 3.981 | DV9: 3.981 | DW9: MEDIUM | DX9: MEDIUM | DY9: HIGH | DZ9: MEDIUM | EA9: 492.765 | EB9: =IF(EA9<510,"low","high") -> low | EC9: 272.622 | ED9: 198.239 | EE9: 71.846 | EF9: MEDIUM | EG9: MEDIUM | EH9: HIGH | EI9: MEDIUM | EJ9: High | EK9: Moderate drinker | EL9: No | EM9: Never | EN9: Plausible_reporter | EO9: Plausible_reporter
A10: MI_009 | B10: Medellín | C10: Men | D10: 56 | E10: 41-60 | F10: 173 | G10: 51 | H10: Normal | I10: 32 | J10: 109 | K10: 192 | L10: 160 | M10: 3.7647059 | N10: =LOG10(L10/G10) -> 0.49654981 | O10: =IF(N10<0.1,"Low", IF(N10<=0.26, "Medium", "High")) -> High | P10: 202 | Q10: 3.52 | R10: 96 | S10: 5.29 | T10: 2.1 | U10: 3.63 | V10: 0.5785124 | W10: 4.37 | X10: 5.328 | Y10: 57.2 | Z10: 47.811816 | AA10: 172.2 | AB10: 96.635537 | AC10: 1.034816 | AD10: 0.3807083 | AE10: 74.2 | AF10: 1.644 | AG10: 27.453662 | AH10: Overweight | AI10: 39.19816 | AJ10: 98.8 | AK10: Central.Obesity | AL10: Abdominal obesity | AM10: Yes | AN10: No | AO10: Vigorous | AP10: 145 | AQ10: 90 | AR10: 1543.07 | AS10: 12.1031 | AT10: 541.563 | AU10: 863.203 | AV10: 12.0674 | AW10: 1120.77 | AX10: 2613.98 | AY10: 183.658 | AZ10: 10.2208 | BA10: 0.970684 | BB10: 2.63337 | BC10: 724.35 | BD10: 0.806656 | BE10: 1.69403 | BF10: 11.8794 | BG10: 4.04536 | BH10: 1.34259 | BI10: 256.374 | BJ10: 7.17962 | BK10: 91.2384 | BL10: 26.111694 | BM10: 8.6627999 | BN10: 2.6555859 | BO10: 0.2769916 | BP10: Abnormal | BQ10: TRUE | BR10: TRUE | BS10: FALSE | BT10: FALSE | BU10: TRUE | BV10: FALSE | BW10: 204.94784 | BX10: 30.444592 | BY10: 12.130056 | BZ10: 5.2115868 | CA10: 1.3095248 | CB10: 1.513257 | CC10: 0.98072394 | CD10: =IF(CC10<=_xlfn.PERCENTILE.EXC(CC$2:CC$312, 1/3), "Low", IF(CC10<=_xlfn.PERCENTILE.EXC(CC$2:CC$312, 2/3), "Medium", "High")) -> High | CE10: =IF(CC10<MEDIAN(CC10:CC460),"antiinflamatoria","proinflamatoria") -> proinflamatoria | CF10: 30.720648 | CG10: High-fat | CH10: 0.22459467 | CI10: 0.67788711 | CJ10: 0.016173366 | CK10: 0.034258854 | CL10: 0.015376648 | CM10: 590.201 | CN10: =IF(CM10>1000, "High","low") -> low | CO10: 372.82 | CP10: 238.001 | CQ10: 134.819 | CR10: 19.157 | CS10: 349.737 | CT10: 2.782 | CU10: 0 | CV10: 2.782 | CW10: 0.018 | CX10: 1.126 | CY10: 1.144 | CZ10: 0 | DA10: 0.263 | DB10: 0 | DC10: 0 | DD10: 11.805 | DE10: 0.026 | DF10: 0.183 | DG10: 0.209 | DH10: 0.001 | DI10: 0.018 | DJ10: 0.019 | DK10: 5.546 | DL10: 1.578 | DM10: 7.124 | DN10: 0.164 | DO10: 0.527 | DP10: 0.691 | DQ10: 217.641 | DR10: 131.37 | DS10: 349.011 | DT10: 0.018 | DU10: 1.126 | DV10: 1.144 | DW10: LOW | DX10: MEDIUM | DY10: LOW | DZ10: MEDIUM | EA10: 382.485 | EB10: =IF(EA10<510,"low","high") -> low | EC10: 241.609 | ED10: 12.415 | EE10: 226.65 | EF10: LOW | EG10: MEDIUM | EH10: LOW | EI10: MEDIUM | EJ10: High | EK10: Never | EL10: Yes | EM10: Current | EN10: Under_reporter | EO10: Under_reporter
A11: MI_010 | B11: Medellín | C11: Men | D11: 55 | E11: 41-60 | F11: 71.9 | G11: 18 | H11: Low | I11: 19 | J11: 30 | K11: 67 | L11: 95 | M11: 3.7222222 | N11: =LOG10(L11/G11) -> 0.7224511 | O11: =IF(N11<0.1,"Low", IF(N11<=0.26, "Medium", "High")) -> High | P11: 41 | Q11: 1.45 | R11: 133 | S11: 7.5 | T11: 1.62 | U11: 2.88 | V11: 0.5625 | W11: 16.13 | X11: 7.3815 | Y11: 74.6 | Z11: 83.112199 | AA11: 44.3 | AB11: 18.897464 | AC11: 5.2917153 | AD11: 0.29981265 | AE11: 71 | AF11: 1.63 | AG11: 26.722873 | AH11: Overweight | AI11: 35.670634 | AJ11: 94.3 | AK11: Central.Obesity | AL11: Abdominal obesity | AM11: No | AN11: No | AO11: Vigorous | AP11: 119 | AQ11: 72 | AR11: 2635.61 | AS11: 31.8487 | AT11: 899.643 | AU11: 1420.2 | AV11: 15.9205 | AW11: 1425.54 | AX11: 5413.53 | AY11: 388.188 | AZ11: 10.9799 | BA11: 3.31186 | BB11: 3.63529 | BC11: 733.729 | BD11: 1.64098 | BE11: 2.31587 | BF11: 18.0851 | BG11: 7.18295 | BH11: 1.5187 | BI11: 528.7 | BJ11: 7.20681 | BK11: 138.246 | BL11: 13.700481 | BM11: 5.7664023 | BN11: 1.7609309 | BO11: 0.028663489 | BP11: Abnormal | BQ11: TRUE | BR11: FALSE | BS11: TRUE | BT11: TRUE | BU11: FALSE | BV11: TRUE | BW11: 87.920085 | BX11: 34.191578 | BY11: 33.556401 | BZ11: 28.109502 | CA11: 112.95078 | CB11: -0.44857205 | CC11: -0.17017149 | CD11: =IF(CC11<=_xlfn.PERCENTILE.EXC(CC$2:CC$312, 1/3), "Low", IF(CC11<=_xlfn.PERCENTILE.EXC(CC$2:CC$312, 2/3), "Medium", "High")) -> Low | CE11: =IF(CC11<MEDIAN(CC11:CC460),"antiinflamatoria","proinflamatoria") -> antiinflamatoria | CF11: 29.42948 | CG11: High-fat | CH11: 0.13577782 | CI11: 0.40565245 | CJ11: 0.15735098 | CK11: 0.044547174 | CL11: 0.027351685 | CM11: 1356.139 | CN11: =IF(CM11>1000, "High","low") -> High | CO11: 825.559 | CP11: 605.692 | CQ11: 219.867 | CR11: 295.49 | CS11: 517.113 | CT11: 4.518 | CU11: 0 | CV11: 4.518 | CW11: 0 | CX11: 8.438 | CY11: 8.438 | CZ11: 0 | DA11: 1.726 | DB11: 0 | DC11: 0 | DD11: 244.323 | DE11: 0.217 | DF11: 8.672 | DG11: 8.888 | DH11: 13.799 | DI11: 0.402 | DJ11: 14.201 | DK11: 26.426 | DL11: 1.576 | DM11: 28.003 | DN11: 0.358 | DO11: 3.533 | DP11: 3.891 | DQ11: 315.942 | DR11: 197.213 | DS11: 513.155 | DT11: 0 | DU11: 8.438 | DV11: 8.438 | DW11: HIGH | DX11: HIGH | DY11: HIGH | DZ11: HIGH | EA11: 514.545 | EB11: =IF(EA11<510,"low","high") -> high | EC11: 313.233 | ED11: 112.115 | EE11: 196.202 | EF11: MEDIUM | EG11: MEDIUM | EH11: MEDIUM | EI11: MEDIUM | EJ11: High | EK11: Never | EL11: No | EM11: Former | EN11: Over_reporter | EO11: Over_reporter
A12: MI_011 | B12: Medellín | C12: Female | D12: 22 | E12: 18-40 | F12: 113 | G12: 73 | H12: Normal | I12: 11 | J12: 122 | K12: 206 | L12: 54 | M12: 2.8219178 | N12: =LOG10(L12/G12) -> -0.1309291 | O12: =IF(N12<0.1,"Low", IF(N12<=0.26, "Medium", "High")) -> Low | P12: 222.3 | Q12: 6.13 | R12: 75 | S12: 5.6 | T12: 16.15 | U12: 6.23 | V12: 2.5922953 | W12: 11.71 | X12: 4.1625 | Y12: 181.8 | Z12: 353.50943 | AA12: 69.7 | AB12: 46.160593 | AC12: 2.16635 | AD12: 0.33926499 | AE12: 62.1 | AF12: 1.481 | AG12: 28.312713 | AH12: Overweight | AI12: 37.406417 | AJ12: 76.9 | AK12: Normal | AL12: Normal | AM12: No | AN12: Yes | AO12: Vigorous | AP12: 113 | AQ12: 75 | AR12: 2211.79 | AS12: 10.5642 | AT12: 742.16 | AU12: 1057.49 | AV12: 12.9838 | AW12: 1652.31 | AX12: 2131 | AY12: 190.572 | AZ12: 10.0625 | BA12: 1.26726 | BB12: 2.47049 | BC12: 806.568 | BD12: 1.08425 | BE12: 1.69779 | BF12: 14.965 | BG12: 4.95161 | BH12: 2.64676 | BI12: 311.591 | BJ12: 6.91812 | BK12: 101.883 | BL12: 6.752309 | BM12: 1.2592243 | BN12: 0.55733007 | BO12: 0.056319572 | BP12: Healthy | BQ12: FALSE | BR12: FALSE | BS12: FALSE | BT12: FALSE | BU12: TRUE | BV12: FALSE | BW12: 102.95052 | BX12: 17.12132 | BY12: 14.068469 | BZ12: 10.960898 | CA12: 47.662092 | CB12: 1.2445745 | CC12: 0.56264669 | CD12: =IF(CC12<=_xlfn.PERCENTILE.EXC(CC$2:CC$312, 1/3), "Low", IF(CC12<=_xlfn.PERCENTILE.EXC(CC$2:CC$312, 2/3), "Medium", "High")) -> High | CE12: =IF(CC12<MEDIAN(CC12:CC460),"antiinflamatoria","proinflamatoria") -> proinflamatoria | CF12: 37.482445 | CG12: High-fat | CH12: 0.000164551 | CI12: 0.55785014 | CJ12: 0.22938478 | CK12: 0.042351441 | CL12: 0.02283152 | CM12: 384.49 | CN12: =IF(CM12>1000, "High","low") -> low | CO12: 90.819 | CP12: 48.901 | CQ12: 41.918 | CR12: 60.749 | CS12: 27.144 | CT12: 2.616 | CU12: 0 | CV12: 2.616 | CW12: 0 | CX12: 0.31 | CY12: 0.31 | CZ12: 0 | DA12: 2.616 | DB12: 0 | DC12: 0 | DD12: 9.444 | DE12: 0 | DF12: 24.675 | DG12: 24.675 | DH12: 25.484 | DI12: 0.889 | DJ12: 26.373 | DK12: 0 | DL12: 0.257 | DM12: 0.257 | DN12: 0.139 | DO12: 1.046 | DP12: 1.184 | DQ12: 11.214 | DR12: 14.737 | DS12: 25.951 | DT12: 0 | DU12: 0.31 | DV12: 0.31 | DW12: LOW | DX12: LOW | DY12: MEDIUM | DZ12: LOW | EA12: 173.837 | EB12: =IF(EA12<510,"low","high") -> low | EC12: 41.062 | ED12: 27.466 | EE12: 12.272 | EF12: LOW | EG12: LOW | EH12: LOW | EI12: LOW | EJ12: High | EK12: Moderate drinker | EL12: No | EM12: Never | EN12: Plausible_reporter | EO12: Plausible_reporter
A13: MI_012 | B13: Medellín | C13: Men | D13: 52 | E13: 41-60 | F13: 50.9 | G13: 44 | H13: Normal | I13: 26 | J13: 88 | K13: 158 | L13: 128 | M13: 3.5909091 | N13: =LOG10(L13/G13) -> 0.46375729 | O13: =IF(N13<0.1,"Low", IF(N13<=0.26, "Medium", "High")) -> High | P13: 180.4 | Q13: 2.32 | R13: 79 | S13: 4.95 | T13: 12.64 | U13: 6.36 | V13: 1.9874214 | W13: 29.18 | X13: 4.3845 | Y13: 302.7 | Z13: 659.8078 | AA13: 28.4 | AB13: 17.586408 | AC13: 5.6862093 | AD13: 0.29703182 | AE13: 96.8 | AF13: 1.701 | AG13: 33.455439 | AH13: Obesity | AI13: 46.107827 | AJ13: 113.4 | AK13: Central.Obesity | AL13: Abdominal obesity | AM13: No | AN13: No | AO13: Vigorous | AP13: 136 | AQ13: 100 | AR13: 1716.45 | AS13: 16.9821 | AT13: 292.037 | AU13: 775.61 | AV13: 12.2535 | AW13: 1233.71 | AX13: 2792 | AY13: 240.922 | AZ13: 10.3961 | BA13: 1.37945 | BB13: 3.53603 | BC13: 712.714 | BD13: 1.01696 | BE13: 1.72071 | BF13: 16.2272 | BG13: 4.68795 | BH13: 1.29817 | BI13: 333.262 | BJ13: 6.98226 | BK13: 179.692 | BL13: 10.537764 | BM13: 3.0313857 | BN13: 1.3567439 | BO13: 0.046780859 | BP13: Abnormal | BQ13: TRUE | BR13: FALSE | BS13: FALSE | BT13: FALSE | BU13: FALSE | BV13: TRUE | BW13: NA | BX13: NA | BY13: NA | BZ13: NA | CA13: NA | CB13: -0.5210655 | CC13: -0.30365123 | CD13: =IF(CC13<=_xlfn.PERCENTILE.EXC(CC$2:CC$312, 1/3), "Low", IF(CC13<=_xlfn.PERCENTILE.EXC(CC$2:CC$312, 2/3), "Medium", "High")) -> Low | CE13: =IF(CC13<MEDIAN(CC13:CC460),"antiinflamatoria","proinflamatoria") -> antiinflamatoria | CF13: 34 | CG13: High-fat | CH13: 0.017255794 | CI13: 0.62655921 | CJ13: 0.043975521 | CK13: 0.021101562 | CL13: 0.012975287 | CM13: 759.456 | CN13: =IF(CM13>1000, "High","low") -> low | CO13: 360.016 | CP13: 192.378 | CQ13: 167.638 | CR13: 211.62 | CS13: 136.246 | CT13: 5.687 | CU13: 0 | CV13: 5.687 | CW13: 0 | CX13: 6.464 | CY13: 6.464 | CZ13: 0 | DA13: 0.737 | DB13: 0 | DC13: 0 | DD13: 69.632 | DE13: 83.737 | DF13: 34.495 | DG13: 118.232 | DH13: 19.855 | DI13: 0.588 | DJ13: 20.443 | DK13: 2.401 | DL13: 0.913 | DM13: 3.313 | DN13: 0.249 | DO13: 5.486 | DP13: 5.735 | DQ13: 10.771 | DR13: 119.645 | DS13: 130.416 | DT13: 0 | DU13: 6.464 | DV13: 6.464 | DW13: MEDIUM | DX13: LOW | DY13: MEDIUM | DZ13: MEDIUM | EA13: 442.457 | EB13: =IF(EA13<510,"low","high") -> low | EC13: 209.745 | ED13: 123.289 | EE13: 79.376 | EF13: MEDIUM | EG13: MEDIUM | EH13: MEDIUM | EI13: MEDIUM | EJ13: High | EK13: Never | EL13: No | EM13: Former | EN13: Plausible_reporter | EO13: Plausible_reporter
A14: MI_013 | B14: Medellín | C14: Men | D14: 55 | E14: 41-60 | F14: 75.7 | G14: 71 | H14: Normal | I14: 31 | J14: 112 | K14: 214 | L14: 154 | M14: 3.0140845 | N14: =LOG10(L14/G14) -> 0.33626237 | O14: =IF(N14<0.1,"Low", IF(N14<=0.26, "Medium", "High")) -> High | P14: 131.6 | Q14: 2.92 | R14: 134 | S14: 8.28 | T14: 8.81 | U14: 3.35 | V14: 2.6298507 | W14: 16.07 | X14: 7.437 | Y14: 73.4 | Z14: 81.635763 | AA14: 44.4 | AB14: 18.826468 | AC14: 5.3116707 | AD14: 0.29966579 | AE14: 97.5 | AF14: 1.675 | AG14: 34.751615 | AH14: Obesity | AI14: 46.638041 | AJ14: 111.5 | AK14: Central.Obesity | AL14: Abdominal obesity | AM14: No | AN14: No | AO14: Light | AP14: 158 | AQ14: 88 | AR14: 2198.05 | AS14: 25.1374 | AT14: 947.472 | AU14: 1346.24 | AV14: 15.3475 | AW14: 1374.18 | AX14: 4504.13 | AY14: 348.556 | AZ14: 11.8894 | BA14: 1.77588 | BB14: 2.84922 | BC14: 771.762 | BD14: 1.19812 | BE14: 2.11426 | BF14: 13.5816 | BG14: 6.9337 | BH14: 2.74255 | BI14: 401.421 | BJ14: 8.22332 | BK14: 218.175 | BL14: 21.169538 | BM14: 3.96713 | BN14: 0.80839512 | BO14: 0.23077782 | BP14: Abnormal | BQ14: TRUE | BR14: TRUE | BS14: TRUE | BT14: TRUE | BU14: FALSE | BV14: TRUE | BW14: 96.442348 | BX14: 20.000663 | BY14: 13.860686 | BZ14: 5.6788837 | CA14: 34.840098 | CB14: -0.3329523 | CC14: -0.15147966 | CD14: =IF(CC14<=_xlfn.PERCENTILE.EXC(CC$2:CC$312, 1/3), "Low", IF(CC14<=_xlfn.PERCENTILE.EXC(CC$2:CC$312, 2/3), "Medium", "High")) -> Low | CE14: =IF(CC14<MEDIAN(CC14:CC460),"antiinflamatoria","proinflamatoria") -> antiinflamatoria | CF14: 33.955157 | CG14: High-fat | CH14: 0.12816563 | CI14: 0.051664537 | CJ14: 0.098895318 | CK14: 0.135192 | CL14: 0.25208537 | CM14: 3642.463 | CN14: =IF(CM14>1000, "High","low") -> High | CO14: 593.252 | CP14: 62.738 | CQ14: 530.514 | CR14: 47.367 | CS14: 510.26 | CT14: 0.131 | CU14: 0 | CV14: 0.131 | CW14: 0 | CX14: 35.494 | CY14: 35.494 | CZ14: 0 | DA14: 0.069 | DB14: 0 | DC14: 0 | DD14: 46.264 | DE14: 0 | DF14: 0 | DG14: 0 | DH14: 0.672 | DI14: 0.001 | DJ14: 0.673 | DK14: 0.325 | DL14: 0.105 | DM14: 0.43 | DN14: 0.973 | DO14: 6.588 | DP14: 7.56 | DQ14: 14.085 | DR14: 488.038 | DS14: 502.123 | DT14: 0 | DU14: 35.494 | DV14: 35.494 | DW14: HIGH | DX14: MEDIUM | DY14: LOW | DZ14: HIGH | EA14: 1657.134 | EB14: =IF(EA14<510,"low","high") -> high | EC14: 269.899 | ED14: 21.549 | EE14: 232.142 | EF14: HIGH | EG14: MEDIUM | EH14: LOW | EI14: MEDIUM | EJ14: Low | EK14: Never | EL14: No | EM14: Never | EN14: Plausible_reporter | EO14: Plausible_reporter
A15: MI_014 | B15: Medellín | C15: Female | D15: 32 | E15: 18-40 | F15: 51.5 | G15: 52 | H15: Normal | I15: 15 | J15: 96 | K15: 163 | L15: 76 | M15: 3.1346154 | N15: =LOG10(L15/G15) -> 0.16481025 | O15: =IF(N15<0.1,"Low", IF(N15<=0.26, "Medium", "High")) -> Medium | P15: 199.7 | Q15: 9.39 | R15: 78 | S15: 5.03 | T15: 25.9 | U15: 6.76 | V15: 3.8313609 | W15: 17.79 | X15: 4.329 | Y15: 222.6 | Z15: 429.1918 | AA15: 45.9 | AB15: 29.215881 | AC15: 3.422796 | AD15: 0.31784366 | AE15: 71.4 | AF15: 1.583 | AG15: 28.492882 | AH15: Overweight | AI15: 40.316714 | AJ15: 90 | AK15: Central.Obesity | AL15: Abdominal obesity | AM15: No | AN15: Yes | AO15: Vigorous | AP15: 124 | AQ15: 80 | AR15: 2264.43 | AS15: 21.3019 | AT15: 1212.89 | AU15: 1322.48 | AV15: 13.3513 | AW15: 1317.15 | AX15: 3768.65 | AY15: 260.669 | AZ15: 10.6849 | BA15: 1.5055 | BB15: 2.7435 | BC15: 965.211 | BD15: 1.30694 | BE15: 2.16771 | BF15: 11.2841 | BG15: 4.91171 | BH15: 1.19962 | BI15: 430.724 | BJ15: 7.3018 | BK15: 243.858 | BL15: 4.9307412 | BM15: 2.033921 | BN15: 2.6279055 | BO15: 0.060833982 | BP15: Abnormal | BQ15: FALSE | BR15: FALSE | BS15: FALSE | BT15: FALSE | BU15: TRUE | BV15: TRUE | BW15: 72.810422 | BX15: 11.425351 | BY15: 6.1453537 | BZ15: 3.2777342 | CA15: 11.186587 | CB15: -0.22297676 | CC15: -0.098487968 | CD15: =IF(CC15<=_xlfn.PERCENTILE.EXC(CC$2:CC$312, 1/3), "Low", IF(CC15<=_xlfn.PERCENTILE.EXC(CC$2:CC$312, 2/3), "Medium", "High")) -> Medium | CE15: =IF(CC15<MEDIAN(CC15:CC460),"antiinflamatoria","proinflamatoria") -> antiinflamatoria | CF15: 40.822222 | CG15: High-fat | CH15: 0.059330804 | CI15: 0.5838795 | CJ15: 0.10126097 | CK15: 0.10183588 | CL15: 0.044919704 | CM15: 735.89 | CN15: =IF(CM15>1000, "High","low") -> low | CO15: 351.287 | CP15: 346.174 | CQ15: 5.113 | CR15: 267.364 | CS15: 83.616 | CT15: 0.251 | CU15: 0 | CV15: 0.251 | CW15: 0 | CX15: 0.056 | CY15: 0.056 | CZ15: 0 | DA15: 0.251 | DB15: 65.723 | DC15: 0 | DD15: 177.826 | DE15: 0 | DF15: 0 | DG15: 0 | DH15: 2.441 | DI15: 0 | DJ15: 2.441 | DK15: 19.649 | DL15: 0.203 | DM15: 19.852 | DN15: 0.925 | DO15: 0.236 | DP15: 1.16 | DQ15: 77.837 | DR15: 4.619 | DS15: 82.456 | DT15: 0 | DU15: 0.056 | DV15: 0.056 | DW15: MEDIUM | DX15: LOW | DY15: HIGH | DZ15: LOW | EA15: 324.978 | EB15: =IF(EA15<510,"low","high") -> low | EC15: 155.133 | ED15: 118.071 | EE15: 36.926 | EF15: LOW | EG15: LOW | EH15: MEDIUM | EI15: LOW | EJ15: High | EK15: Moderate drinker | EL15: No | EM15: Never | EN15: Plausible_reporter | EO15: Plausible_reporter
A16: MI_015 | B16: Medellín | C16: Men | D16: 34 | E16: 18-40 | F16: 79.9 | G16: 40 | H16: Normal | I16: 25 | J16: 144 | K16: 209 | L16: 123 | M16: 5.225 | N16: =LOG10(L16/G16) -> 0.48784512 | O16: =IF(N16<0.1,"Low", IF(N16<=0.26, "Medium", "High")) -> High | P16: 241.9 | Q16: 0.48 | R16: 83 | S16: 5.55 | T16: 2.47 | U16: 3.5 | V16: 0.70571429 | W16: 10.8 | X16: 4.6065 | Y16: 140.7 | Z16: 195.21012 | AA16: 73.3 | AB16: 45.225949 | AC16: 2.21112 | AD16: 0.33824554 | AE16: 74.1 | AF16: 1.701 | AG16: 25.61 | AH16: Overweight | AI16: 34.896469 | AJ16: 92.9 | AK16: Central.Obesity | AL16: Abdominal obesity | AM16: No | AN16: Yes | AO16: Vigorous | AP16: 114 | AQ16: 72 | AR16: 3263.2 | AS16: 16.0602 | AT16: 1753.03 | AU16: 1870.87 | AV16: 16.6254 | AW16: 2584.88 | AX16: 4843.72 | AY16: 345.18 | AZ16: 11.2905 | BA16: 2.6833 | BB16: 3.69428 | BC16: 1044.93 | BD16: 1.75315 | BE16: 2.69256 | BF16: 20.6199 | BG16: 7.1479 | BH16: 1.86607 | BI16: 374.174 | BJ16: 7.7801 | BK16: 254.896 | BL16: 2.8497728 | BM16: 0.76603706 | BN16: 0.23661078 | BO16: 0.009773476 | BP16: Healthy | BQ16: FALSE | BR16: FALSE | BS16: FALSE | BT16: FALSE | BU16: FALSE | BV16: FALSE | BW16: 30.335235 | BX16: 8.7885877 | BY16: 5.1266939 | BZ16: 2.8744043 | CA16: 21.807698 | CB16: -0.42584279 | CC16: -0.13050653 | CD16: =IF(CC16<=_xlfn.PERCENTILE.EXC(CC$2:CC$312, 1/3), "Low", IF(CC16<=_xlfn.PERCENTILE.EXC(CC$2:CC$312, 2/3), "Medium", "High")) -> Medium | CE16: =IF(CC16<MEDIAN(CC16:CC460),"antiinflamatoria","proinflamatoria") -> antiinflamatoria | CF16: 27.379978 | CG16: High-fat | CH16: 0.18766827 | CI16: 0.32566136 | CJ16: 0.003058059 | CK16: 0.16200398 | CL16: 0.23059815 | CM16: 1544.982 | CN16: =IF(CM16>1000, "High","low") -> High | CO16: 657.462 | CP16: 353.175 | CQ16: 304.287 | CR16: 189.024 | CS16: 463.246 | CT16: 2.2 | CU16: 0 | CV16: 2.2 | CW16: 0 | CX16: 2.991 | CY16: 2.991 | CZ16: 0 | DA16: 0.224 | DB16: 0.552 | DC16: 0 | DD16: 31.864 | DE16: 0 | DF16: 25.028 | DG16: 25.028 | DH16: 0 | DI16: 0.915 | DJ16: 0.915 | DK16: 130.373 | DL16: 0.293 | DM16: 130.666 | DN16: 1.15 | DO16: 13.317 | DP16: 14.467 | DQ16: 186.94 | DR16: 261.645 | DS16: 448.585 | DT16: 0 | DU16: 2.991 | DV16: 2.991 | DW16: HIGH | DX16: MEDIUM | DY16: MEDIUM | DZ16: MEDIUM | EA16: 473.456 | EB16: =IF(EA16<510,"low","high") -> low | EC16: 201.478 | ED16: 57.926 | EE16: 141.961 | EF16: MEDIUM | EG16: MEDIUM | EH16: MEDIUM | EI16: MEDIUM | EJ16: High | EK16: Moderate drinker | EL16: No | EM16: Never | EN16: Over_reporter | EO16: Over_reporter
A17: MI_016 | B17: Medellín | C17: Female | D17: 45 | E17: 41-60 | F17: 59.3 | G17: 51 | H17: Normal | I17: 8 | J17: 116 | K17: 175 | L17: 42 | M17: 3.4313725 | N17: =LOG10(L17/G17) -> -0.084320886 | O17: =IF(N17<0.1,"Low", IF(N17<=0.26, "Medium", "High")) -> Low | P17: 45.3 | Q17: 2.34 | R17: 81 | S17: 5.4 | T17: 11.45 | U17: 5.15 | V17: 2.223301 | W17: 6.25 | X17: 4.4955 | Y17: 102.4 | Z17: 125.56504 | AA17: 126.4 | AB17: 80.08008 | AC17: 1.24875 | AD17: 0.36923595 | AE17: 71.9 | AF17: 1.603 | AG17: 27.980911 | AH17: Overweight | AI17: 41.58097 | AJ17: 91.1 | AK17: Central.Obesity | AL17: Abdominal obesity | AM17: No | AN17: No | AO17: Vigorous | AP17: 106 | AQ17: 72 | AR17: 1215.09 | AS17: 14.3342 | AT17: 439.939 | AU17: 722.073 | AV17: 10.8817 | AW17: 822.855 | AX17: 2065.13 | AY17: 192.359 | AZ17: 9.02706 | BA17: 0.849392 | BB17: 2.63441 | BC17: 686.429 | BD17: 0.879273 | BE17: 1.28593 | BF17: 13.233 | BG17: 3.18807 | BH17: 1.54982 | BI17: 328.557 | BJ17: 7.06382 | BK17: 134.098 | BL17: 0.91739789 | BM17: 0.45943481 | BN17: 0.386831 | BO17: 0 | BP17: Healthy | BQ17: FALSE | BR17: FALSE | BS17: FALSE | BT17: FALSE | BU17: FALSE | BV17: FALSE | BW17: 59.27851 | BX17: 16.350023 | BY17: 5.4001071 | BZ17: 3.2312831 | CA17: 1.2638728 | CB17: 0.46726201 | CC17: 0.38457779 | CD17: =IF(CC17<=_xlfn.PERCENTILE.EXC(CC$2:CC$312, 1/3), "Low", IF(CC17<=_xlfn.PERCENTILE.EXC(CC$2:CC$312, 2/3), "Medium", "High")) -> High | CE17: =IF(CC17<MEDIAN(CC17:CC460),"antiinflamatoria","proinflamatoria") -> proinflamatoria | CF17: 40.807903 | CG17: High-fat | CH17: 0.18941583 | CI17: 0.49503769 | CJ17: 0.083165829 | CK17: 0.07330402 | CL17: 0.055150754 | CM17: 651.872 | CN17: =IF(CM17>1000, "High","low") -> low | CO17: 407.815 | CP17: 357.598 | CQ17: 50.217 | CR17: 164.002 | CS17: 176.774 | CT17: 66.082 | CU17: 0 | CV17: 66.082 | CW17: 0 | CX17: 0.957 | CY17: 0.957 | CZ17: 0 | DA17: 66.082 | DB17: 131.447 | DC17: 0 | DD17: 3.922 | DE17: 0.001 | DF17: 0.008 | DG17: 0.01 | DH17: 3.7 | DI17: 0.026 | DJ17: 3.726 | DK17: 24.689 | DL17: 0.208 | DM17: 24.897 | DN17: 1.034 | DO17: 1.303 | DP17: 2.337 | DQ17: 126.706 | DR17: 47.697 | DS17: 174.403 | DT17: 0 | DU17: 0.957 | DV17: 0.957 | DW17: LOW | DX17: MEDIUM | DY17: MEDIUM | DZ17: MEDIUM | EA17: 536.48 | EB17: =IF(EA17<510,"low","high") -> high | EC17: 335.625 | ED17: 134.971 | EE17: 145.483 | EF17: MEDIUM | EG17: MEDIUM | EH17: HIGH | EI17: MEDIUM | EJ17: High | EK17: Never | EL17: No | EM17: Never | EN17: Under_reporter | EO17: Under_reporter
A18: MI_017 | B18: Medellín | C18: Men | D18: 37 | E18: 18-40 | F18: 92.1 | G18: 11 | H18: Low | I18: 89 | J18: NA | K18: 176 | L18: 446 | M18: 16 | N18: =LOG10(L18/G18) -> 1.6079422 | O18: =IF(N18<0.1,"Low", IF(N18<=0.26, "Medium", "High")) -> High | P18: 116.5 | Q18: 4.3 | R18: 335 | S18: 10.77 | T18: 14.52 | U18: 1.3 | V18: 11.169231 | W18: 57.07 | X18: 18.5925 | Y18: 57.7 | Z18: 75.626967 | AA18: 7.4 | AB18: 2.1204931 | AC18: 47.158843 | AD18: 0.23335137 | AE18: 119.4 | AF18: 1.69 | AG18: 41.805259 | AH18: Obesity | AI18: 42.676586 | AJ18: 131.3 | AK18: Central.Obesity | AL18: Abdominal obesity | AM18: No | AN18: Yes | AO18: Vigorous | AP18: 141 | AQ18: 91 | AR18: 2080.81 | AS18: 12.9978 | AT18: 660.977 | AU18: 988.176 | AV18: 12.5911 | AW18: 1786.51 | AX18: 2991.61 | AY18: 179.586 | AZ18: 10.0224 | BA18: 1.24664 | BB18: 3.52969 | BC18: 718.462 | BD18: 1.188 | BE18: 1.93001 | BF18: 15.4679 | BG18: 4.11499 | BH18: 1.1876 | BI18: 327.528 | BJ18: 7.03609 | BK18: 145.357 | BL18: 13.402068 | BM18: 2.1516663 | BN18: 0.70588382 | BO18: 0.08834796 | BP18: Abnormal | BQ18: TRUE | BR18: TRUE | BS18: TRUE | BT18: TRUE | BU18: TRUE | BV18: TRUE | BW18: 204.61071 | BX18: 22.459983 | BY18: 8.658455 | BZ18: 4.4998775 | CA18: 1.3409844 | CB18: 1.1853462 | CC18: 0.56960412 | CD18: =IF(CC18<=_xlfn.PERCENTILE.EXC(CC$2:CC$312, 1/3), "Low", IF(CC18<=_xlfn.PERCENTILE.EXC(CC$2:CC$312, 2/3), "Medium", "High")) -> High | CE18: =IF(CC18<MEDIAN(CC18:CC460),"antiinflamatoria","proinflamatoria") -> proinflamatoria | CF18: 38.257426 | CG18: High-fat | CH18: 0.1256871 | CI18: 0.55539112 | CJ18: 0.023220578 | CK18: 0.079457364 | CL18: 0.051162791 | CM18: 595.189 | CN18: =IF(CM18>1000, "High","low") -> low | CO18: 1162.727 | CP18: 966.603 | CQ18: 196.123 | CR18: 630.842 | CS18: 525.18 | CT18: 6.41 | CU18: 0 | CV18: 6.41 | CW18: 0 | CX18: 0.295 | CY18: 0.295 | CZ18: 0 | DA18: 2.923 | DB18: 0 | DC18: 0 | DD18: 69.387 | DE18: 0 | DF18: 0 | DG18: 0 | DH18: 24.625 | DI18: 0 | DJ18: 24.625 | DK18: 536.83 | DL18: 0 | DM18: 536.83 | DN18: 0.186 | DO18: 1.52 | DP18: 1.706 | DQ18: 329.144 | DR18: 194.287 | DS18: 523.432 | DT18: 0 | DU18: 0.295 | DV18: 0.295 | DW18: LOW | DX18: HIGH | DY18: HIGH | DZ18: HIGH | EA18: 286.037 | EB18: =IF(EA18<510,"low","high") -> low | EC18: 558.786 | ED18: 303.171 | EE18: 252.392 | EF18: LOW | EG18: HIGH | EH18: HIGH | EI18: HIGH | EJ18: High | EK18: Moderate drinker | EL18: No | EM18: Never | EN18: Plausible_reporter | EO18: Plausible_reporter
A19: MI_018 | B19: Medellín | C19: Female | D19: 52 | E19: 41-60 | F19: 53.4 | G19: 90 | H19: Normal | I19: 14 | J19: 90 | K19: 194 | L19: 68 | M19: 2.1555556 | N19: =LOG10(L19/G19) -> -0.1217336 | O19: =IF(N19<0.1,"Low", IF(N19<=0.26, "Medium", "High")) -> Low | P19: 86.8 | Q19: 4.5 | R19: 76 | S19: 6 | T19: 18.24 | U19: 18.07 | V19: 1.0094079 | W19: 7.39 | X19: 4.218 | Y19: 130.2 | Z19: 205.84958 | AA19: 109.1 | AB19: 72.182431 | AC19: 1.3853787 | AD19: 0.36318887 | AE19: 73.5 | AF19: 1.481 | AG19: 33.510216 | AH19: Obesity | AI19: 43.517106 | AJ19: 97.7 | AK19: Central.Obesity | AL19: Abdominal obesity | AM19: No | AN19: No | AO19: Vigorous | AP19: 118 | AQ19: 75 | AR19: 1819.78 | AS19: 16.7585 | AT19: 638.681 | AU19: 950.37 | AV19: 13.4098 | AW19: 1241.45 | AX19: 2824.28 | AY19: 220.603 | AZ19: 9.96947 | BA19: 1.14189 | BB19: 2.80253 | BC19: 777.737 | BD19: 1.21925 | BE19: 1.63587 | BF19: 12.2037 | BG19: 3.83838 | BH19: 1.28688 | BI19: 311.733 | BJ19: 6.71837 | BK19: 192.646 | BL19: 23.561708 | BM19: 5.7667753 | BN19: 1.3588736 | BO19: 0 | BP19: Healthy | BQ19: FALSE | BR19: FALSE | BS19: FALSE | BT19: FALSE | BU19: TRUE | BV19: FALSE | BW19: 110.99446 | BX19: 14.383708 | BY19: 6.7080584 | BZ19: 2.8751031 | CA19: 0.77352028 | CB19: 0.020934498 | CC19: 0.011502471 | CD19: =IF(CC19<=_xlfn.PERCENTILE.EXC(CC$2:CC$312, 1/3), "Low", IF(CC19<=_xlfn.PERCENTILE.EXC(CC$2:CC$312, 2/3), "Medium", "High")) -> Medium | CE19: =IF(CC19<MEDIAN(CC19:CC460),"antiinflamatoria","proinflamatoria") -> antiinflamatoria | CF19: 45.682702 | CG19: High-fat | CH19: 0.13131563 | CI19: 0.12542982 | CJ19: 0.19491342 | CK19: 0.031628512 | CL19: 0.13754221 | CM19: 730.522 | CN19: =IF(CM19>1000, "High","low") -> low | CO19: 202.704 | CP19: 97.252 | CQ19: 105.452 | CR19: 99.48 | CS19: 99.588 | CT19: 0.004 | CU19: 0 | CV19: 0.004 | CW19: 0 | CX19: 3.631 | CY19: 3.631 | CZ19: 0 | DA19: 0 | DB19: 0 | DC19: 0 | DD19: 48.214 | DE19: 0.268 | DF19: 0 | DG19: 0.268 | DH19: 0 | DI19: 0.108 | DJ19: 0.108 | DK19: 41.433 | DL19: 9.415 | DM19: 50.848 | DN19: 0.761 | DO19: 4.048 | DP19: 4.809 | DQ19: 6.492 | DR19: 88.214 | DS19: 94.706 | DT19: 0 | DU19: 3.631 | DV19: 3.631 | DW19: MEDIUM | DX19: LOW | DY19: MEDIUM | DZ19: LOW | EA19: 401.434 | EB19: =IF(EA19<510,"low","high") -> low | EC19: 111.389 | ED19: 54.666 | EE19: 54.726 | EF19: MEDIUM | EG19: LOW | EH19: MEDIUM | EI19: LOW | EJ19: High | EK19: Never | EL19: No | EM19: Former | EN19: Plausible_reporter | EO19: Plausible_reporter
A20: MI_019 | B20: Medellín | C20: Men | D20: 25 | E20: 18-40 | F20: 87 | G20: 39 | H20: Low | I20: 40 | J20: 147 | K20: 226 | L20: 202 | M20: 5.7948718 | N20: =LOG10(L20/G20) -> 0.71428676 | O20: =IF(N20<0.1,"Low", IF(N20<=0.26, "Medium", "High")) -> High | P20: 280.2 | Q20: 4.68 | R20: 93 | S20: 5.16 | T20: 20.08 | U20: 6.54 | V20: 3.0703364 | W20: 20.35 | X20: 5.1615 | Y20: 173.1 | Z20: 244.95937 | AA20: 38.4 | AB20: 21.42112 | AC20: 4.66829 | AD20: 0.3047872 | AE20: 129.8 | AF20: 1.776 | AG20: 41.151794 | AH20: Obesity | AI20: 44.078742 | AJ20: 126.6 | AK20: Central.Obesity | AL20: Abdominal obesity | AM20: No | AN20: Yes | AO20: Vigorous | AP20: 136 | AQ20: 94 | AR20: 2323.07 | AS20: 19.2032 | AT20: 1156.29 | AU20: 1382.74 | AV20: 16.0468 | AW20: 1733.93 | AX20: 3802.28 | AY20: 269.882 | AZ20: 12.1803 | BA20: 2.39898 | BB20: 3.2419 | BC20: 819.942 | BD20: 1.26269 | BE20: 2.85134 | BF20: 18.7838 | BG20: 5.17335 | BH20: 1.5003 | BI20: 334.608 | BJ20: 7.81998 | BK20: 148.184 | BL20: 1.8987728 | BM20: 0.68895551 | BN20: 0.77334238 | BO20: 0 | BP20: Abnormal | BQ20: TRUE | BR20: TRUE | BS20: TRUE | BT20: FALSE | BU20: TRUE | BV20: TRUE | BW20: 116.78478 | BX20: 20.72482 | BY20: 9.8378523 | BZ20: 3.5887644 | CA20: 1.541458 | CB20: -0.25409663 | CC20: -0.10938297 | CD20: =IF(CC20<=_xlfn.PERCENTILE.EXC(CC$2:CC$312, 1/3), "Low", IF(CC20<=_xlfn.PERCENTILE.EXC(CC$2:CC$312, 2/3), "Medium", "High")) -> Medium | CE20: =IF(CC20<MEDIAN(CC20:CC460),"antiinflamatoria","proinflamatoria") -> antiinflamatoria | CF20: 35.943128 | CG20: High-fat | CH20: 0.05738573 | CI20: 0.26357302 | CJ20: 0.12087514 | CK20: 0.055908584 | CL20: 0.12023411 | CM20: 1174.078 | CN20: =IF(CM20>1000, "High","low") -> High | CO20: 422.438 | CP20: 242.409 | CQ20: 180.029 | CR20: 149.497 | CS20: 207.432 | CT20: 0.532 | CU20: 0 | CV20: 0.532 | CW20: 0 | CX20: 64.978 | CY20: 64.978 | CZ20: 0 | DA20: 0.38 | DB20: 95.707 | DC20: 0 | DD20: 35.204 | DE20: 0 | DF20: 0 | DG20: 0 | DH20: 3.7 | DI20: 0.002 | DJ20: 3.702 | DK20: 9.604 | DL20: 5.28 | DM20: 14.884 | DN20: 29.75 | DO20: 21.768 | DP20: 51.518 | DQ20: 67.862 | DR20: 87.953 | DS20: 155.815 | DT20: 0 | DU20: 64.978 | DV20: 64.978 | DW20: MEDIUM | DX20: MEDIUM | DY20: MEDIUM | DZ20: MEDIUM | EA20: 505.399 | EB20: =IF(EA20<510,"low","high") -> low | EC20: 181.845 | ED20: 64.353 | EE20: 89.292 | EF20: MEDIUM | EG20: LOW | EH20: MEDIUM | EI20: MEDIUM | EJ20: High | EK20: Moderate drinker | EL20: No | EM20: Never | EN20: Plausible_reporter | EO20: Plausible_reporter
A21: MI_020 | B21: Medellín | C21: Female | D21: 58 | E21: 41-60 | F21: 50.2 | G21: 55 | H21: Normal | I21: 24 | J21: 56 | K21: 135 | L21: 118 | M21: 2.4545455 | N21: =LOG10(L21/G21) -> 0.33151932 | O21: =IF(N21<0.1,"Low", IF(N21<=0.26, "Medium", "High")) -> High | P21: 55.1 | Q21: 1.37 | R21: 75 | S21: 5.29 | T21: 15.23 | U21: 3.88 | V21: 3.9252577 | W21: 16.47 | X21: 4.1625 | Y21: 228.4 | Z21: 497.20755 | AA21: 50 | AB21: 32.819705 | AC21: 3.04695 | AD21: 0.32303027 | AE21: 73.3 | AF21: 1.515 | AG21: 31.935867 | AH21: Obesity | AI21: 42.168445 | AJ21: 94.2 | AK21: Central.Obesity | AL21: Abdominal obesity | AM21: No | AN21: No | AO21: Moderate | AP21: 147 | AQ21: 94 | AR21: 1130.19 | AS21: 15.134 | AT21: 611.611 | AU21: 786.295 | AV21: 10.014 | AW21: 978.701 | AX21: 2229.57 | AY21: 176.468 | AZ21: 9.1266 | BA21: 1.09565 | BB21: 4.46585 | BC21: 591.959 | BD21: 0.875694 | BE21: 1.24315 | BF21: 10.5401 | BG21: 3.49882 | BH21: 1.31249 | BI21: 232.707 | BJ21: 6.65138 | BK21: 103.225 | BL21: 6.9163313 | BM21: 1.0640821 | BN21: 0.51133503 | BO21: 0 | BP21: Abnormal | BQ21: TRUE | BR21: FALSE | BS21: TRUE | BT21: FALSE | BU21: FALSE | BV21: TRUE | BW21: 60.288402 | BX21: 18.386049 | BY21: 16.581711 | BZ21: 11.553351 | CA21: 5.2498787 | CB21: 0.9618821 | CC21: 0.85122309 | CD21: =IF(CC21<=_xlfn.PERCENTILE.EXC(CC$2:CC$312, 1/3), "Low", IF(CC21<=_xlfn.PERCENTILE.EXC(CC$2:CC$312, 2/3), "Medium", "High")) -> High | CE21: =IF(CC21<MEDIAN(CC21:CC460),"antiinflamatoria","proinflamatoria") -> proinflamatoria | CF21: 43.834395 | CG21: High-fat | CH21: 4.01e-05 | CI21: 0.5648445 | CJ21: 0.013626162 | CK21: 0.12319654 | CL21: 0.042080795 | CM21: 868.245 | CN21: =IF(CM21>1000, "High","low") -> low | CO21: 344.727 | CP21: 226.535 | CQ21: 118.192 | CR21: 48.72 | CS21: 264.614 | CT21: 2.387 | CU21: 0 | CV21: 2.387 | CW21: 0 | CX21: 29.006 | CY21: 29.006 | CZ21: 0 | DA21: 0.577 | DB21: 0 | DC21: 0 | DD21: 9.19 | DE21: 0 | DF21: 0 | DG21: 0 | DH21: 3.835 | DI21: 0.052 | DJ21: 3.887 | DK21: 29.097 | DL21: 6.545 | DM21: 35.642 | DN21: 1.779 | DO21: 1.442 | DP21: 3.222 | DQ21: 180.246 | DR21: 81.146 | DS21: 261.393 | DT21: 0 | DU21: 29.006 | DV21: 29.006 | DW21: MEDIUM | DX21: LOW | DY21: LOW | DZ21: MEDIUM | EA21: 768.23 | EB21: =IF(EA21<510,"low","high") -> high | EC21: 305.017 | ED21: 43.108 | EE21: 234.133 | EF21: HIGH | EG21: MEDIUM | EH21: MEDIUM | EI21: MEDIUM | EJ21: Moderate | EK21: Never | EL21: No | EM21: Former | EN21: Under_reporter | EO21: Under_reporter
A22: MI_021 | B22: Medellín | C22: Female | D22: 41 | E22: 41-60 | F22: 56 | G22: 50 | H22: Normal | I22: 25 | J22: 80 | K22: 155 | L22: 127 | M22: 3.1 | N22: =LOG10(L22/G22) -> 0.40483372 | O22: =IF(N22<0.1,"Low", IF(N22<=0.26, "Medium", "High")) -> High | P22: 177 | Q22: 0.95 | R22: 80 | S22: 5.02 | T22: 11.28 | U22: 4.71 | V22: 2.3949045 | W22: 11.17 | X22: 4.44 | Y22: 154.9 | Z22: 237.65957 | AA22: 71.6 | AB22: 45.36766 | AC22: 2.2042133 | AD22: 0.33840106 | AE22: 65.3 | AF22: 1.59 | AG22: 25.829674 | AH22: Overweight | AI22: 41.009938 | AJ22: 83.1 | AK22: Central.Obesity | AL22: Normal | AM22: No | AN22: Yes | AO22: Moderate | AP22: 151 | AQ22: 96 | AR22: 1783.41 | AS22: 17.8897 | AT22: 623.009 | AU22: 932.18 | AV22: 12.4462 | AW22: 1238.44 | AX22: 2618.94 | AY22: 227.237 | AZ22: 10.2083 | BA22: 1.38552 | BB22: 3.10383 | BC22: 784.919 | BD22: 1.07899 | BE22: 2.12568 | BF22: 12.751 | BG22: 4.36918 | BH22: 1.66303 | BI22: 340.25 | BJ22: 6.91433 | BK22: 170.973 | BL22: 0.94731851 | BM22: 0.1678553 | BN22: 0.062586084 | BO22: 0 | BP22: Healthy | BQ22: TRUE | BR22: FALSE | BS22: FALSE | BT22: FALSE | BU22: FALSE | BV22: FALSE | BW22: NA | BX22: NA | BY22: NA | BZ22: NA | CA22: NA | CB22: -0.73662595 | CC22: -0.4131385 | CD22: =IF(CC22<=_xlfn.PERCENTILE.EXC(CC$2:CC$312, 1/3), "Low", IF(CC22<=_xlfn.PERCENTILE.EXC(CC$2:CC$312, 2/3), "Medium", "High")) -> Low | CE22: =IF(CC22<MEDIAN(CC22:CC460),"antiinflamatoria","proinflamatoria") -> antiinflamatoria | CF22: 37.732852 | CG22: High-fat | CH22: 0.093751933 | CI22: 0.17321844 | CJ22: 0.00249428 | CK22: 0.06182103 | CL22: 0.18935911 | CM22: 430.167 | CN22: =IF(CM22>1000, "High","low") -> low | CO22: 395.433 | CP22: 332.059 | CQ22: 63.374 | CR22: 324.427 | CS22: 57.195 | CT22: 5.849 | CU22: 0 | CV22: 5.849 | CW22: 0 | CX22: 7.962 | CY22: 7.962 | CZ22: 0 | DA22: 5.847 | DB22: 0 | DC22: 0 | DD22: 65.185 | DE22: 0.172 | DF22: 18.15 | DG22: 18.323 | DH22: 4.035 | DI22: 0.798 | DJ22: 4.832 | DK22: 233.816 | DL22: 2.262 | DM22: 236.078 | DN22: 0.114 | DO22: 2.455 | DP22: 2.569 | DQ22: 22.867 | DR22: 31.735 | DS22: 54.601 | DT22: 0 | DU22: 7.962 | DV22: 7.962 | DW22: LOW | DX22: MEDIUM | DY22: HIGH | DZ22: LOW | EA22: 241.205 | EB22: =IF(EA22<510,"low","high") -> low | EC22: 221.729 | ED22: 181.914 | EE22: 32.07 | EF22: LOW | EG22: MEDIUM | EH22: HIGH | EI22: LOW | EJ22: Moderate | EK22: Moderate drinker | EL22: No | EM22: Never | EN22: Plausible_reporter | EO22: Plausible_reporter
